Workbook

Sheet IN
A1: COMMERCIAL INVOICE
A2: KYUNG CHANG PRECISION. CO.,LTD | H2: KCR26-06 | K2: 46076
A3: 1. For Account & Risk of Messers | G3: 7. Remarks
A4: BORGWARNER TURBO AND EMISSIONS SYSTEMS DE
A5: MEXICO SA DE CV
A6: BLVD. KAPPA No. Ext. 1125
A7: COL. PARQUE INDUSTRIAL SANTA MARIA,
A8: RAMOS ARIZPE C.P.
A9: 25903 COAHUILA DE ZARAGOZA MEXICO
A11: Attention : Jose Luis Zamora.
A12: 2. Notify party
A14: Same as Above
A16: 3. Port of Loading | D16: 4. Final Destination | I16: SA# : 2550000334
A18: BUSAN, KOREA | I18: Tax ID : 503-81-32693
D19: FOB
A21: 5. Carrier | D21: 6. Sailing Date | H21: Terms of delivery and payment
A25: 8.Marks and Numbers of PKGS | E25: 9.Description of | H25: 10.Quantity | J25: 11.Unit | K25: 12.Extended Price | M25: 13.P.O.# | N25: 14.RAN#
E26: Goods | J26: Price
H27: (pcs) | J27: (USD) | K27: (USD)
E29: NEW AUTOMOTIVE PARTS-AIR PUMP BRACKET
B60: 15.Address :
B61: KYUNG CHANG PRECISION IND. CO., LTD.
B62: 149 Gukgasandan-daero 33-gil, Guji-myeon,
B63: Dalseong-gun, Daegu
B64: (tel) : 82-53-589-0133
B65: (fax) : 82-53-582-1786

Sheet PA
A1: PACKING LIST
A2: KYUNG CHANG IND. CO.,LTD | H2: KCR26-06 | K2: 46076
A3: 1. For Account & Risk of Messers | G3: 7. Remarks
A4: BORGWARNER TURBO AND EMISSIONS SYSTEMS DE
A5: MEXICO SA DE CV
A6: BLVD. KAPPA No. Ext. 1125
A7: COL. PARQUE INDUSTRIAL SANTA MARIA,
A8: RAMOS ARIZPE C.P.
A9: 25903 COAHUILA DE ZARAGOZA MEXICO
A11: Attention : Jose Luis Zamora.
A12: 2. Notify party
A14: Same as Above
A16: 3. Port of Loading | D16: 4. Final Destination | H16: SA# : 2550000334
A18: BUSAN, KOREA | H18: Tax ID : 503-81-32693
D19: FOB
A21: 5. Carrier | D21: 6. Sailing Date | H21: Terms of delivery and payment
A25: 8.Marks and Numbers of PKGS | E25: 9.Description of | H25: 10.Quantity | J25: 11.Box | K25: 12.Net | L25: 13.Gross | M25: 14.Measure- | N25: 15.P.O.# | O25: 16.RAN#
E26: Goods | K26: Weight | L26: Weight | M26: ment
H27: (pcs) | J27: (pcs) | K27: (kg) | L27: (kg) | M27: (CBM)
E29: NEW AUTOMOTIVE PARTS-AIR PUMP BRACKET
B61: 17.Address :
B62: 149 Gukgasandan-daero 33-gil, Guji-myeon,
B63: Dalseong-gun, Daegu
B64: DAEGU, KOREA.
B65: (tel) : 82-53-589-0168
E66: (fax) : 82-53-582-1786

Sheet INVOICE
A1: =MASTER!B2 -> E3870015336A0 | B1: =VLOOKUP(A1,MASTER!$B$2:$N$16,2,FALSE) -> 14400 | C1: =VLOOKUP(A1,MASTER!$B$2:$N$16,10,FALSE) -> 0.4653 | D1: =B1*C1 -> 6700.32 | E1: =VLOOKUP(A1,MASTER!$B$2:$N$16,11,FALSE) -> 2550001216 | F1: =VLOOKUP(A1,MASTER!$B$2:$N$16,3,FALSE) -> 60
A2: =MASTER!B3 -> E3870015347A0 | B2: =VLOOKUP(A2,MASTER!$B$2:$N$16,2,FALSE) -> 14400 | C2: =VLOOKUP(A2,MASTER!$B$2:$N$16,10,FALSE) -> 0.3482 | D2: =B2*C2 -> 5014.08 | E2: =VLOOKUP(A2,MASTER!$B$2:$N$16,11,FALSE) -> 2550001217 | F2: =VLOOKUP(A2,MASTER!$B$2:$N$16,3,FALSE) -> 60
A3: TOTAL | B3: =SUM(B1:B2) -> 28800 | D3: =SUM(D1:D2) -> 11714.4

Sheet PACKING
A1: =MASTER!B2 -> E3870015336A0 | B1: =VLOOKUP(A1,MASTER!$B$2:$N$16,2,FALSE) -> 14400 | C1: =VLOOKUP(A1,MASTER!$B$2:$N$16,6,FALSE) -> 72 | D1: =B1*K1 -> 388.8 | E1: =D1*1.023 -> 397.7424 | F1: =MASTER!Q2 -> 1.21 | G1: =VLOOKUP(A1,MASTER!$B$2:$N$16,11,FALSE) -> 2550001216 | H1: =VLOOKUP(A1,MASTER!$B$2:$N$16,3,FALSE) -> 60 | K1: =VLOOKUP(A1,MASTER!$B$2:$N$16,12,FALSE) -> 0.027
A2: =MASTER!B3 -> E3870015347A0 | B2: =VLOOKUP(A2,MASTER!$B$2:$N$16,2,FALSE) -> 14400 | C2: =VLOOKUP(A2,MASTER!$B$2:$N$16,6,FALSE) -> 72 | D2: =B2*K2 -> 360 | E2: =D2*1.023 -> 368.28 | F2: =MASTER!Q3 -> 1.21 | G2: =VLOOKUP(A2,MASTER!$B$2:$N$16,11,FALSE) -> 2550001217 | H2: =VLOOKUP(A2,MASTER!$B$2:$N$16,3,FALSE) -> 60 | K2: =VLOOKUP(A2,MASTER!$B$2:$N$16,12,FALSE) -> 0.025
A3: TOTAL | B3: =SUM(B1:B2) -> 28800 | C3: =SUM(C1:C2) -> 144 | D3: =SUM(D1:D2) -> 748.8 | E3: =SUM(E1:E2) -> 766.0224 | F3: =SUM(F1:F2) -> 2.42
E7: 가로 | F7: 세로 | G7: 높이
D8: Pallet | E8: 1100 | F8: 1100 | G8: 1000
E9: =E8/1000 -> 1.1 | F9: =F8/1000 -> 1.1 | G9: =G8/1000 -> 1 | K9: =E9*F9*G9 -> 1.21

Sheet 쉬핑마크1
C2: 1 | E2: PN : | F2: =MASTER!B2 -> E3870015336A0 | H2: 49R-1897
A3: 1 | B3: =MASTER!B1 -> P/N | E3: Q'TY : | F3: =VLOOKUP(F2,MASTER!$B$2:$M$16,5,FALSE) -> 200 | H3: 34R-15044
A4: 2 | B4: =MASTER!B2 | E4: C/NO : | F4: =VLOOKUP(F2,MASTER!$B$2:$M$16,6,FALSE) -> 72 | H4: 11100011A
A5: 3 | B5: =MASTER!#REF! -> #REF! | E5: MADE IN KOREA | H5: 11100044A
C6: 1 | E6: PN : | F6: E3870015347A0 | H6: 49R-1897
A7: 1 | B7: =MASTER!B5 -> 0 | E7: Q'TY : | F7: =VLOOKUP(F6,MASTER!$B$2:$M$16,5,FALSE) -> 200 | H7: 34R-15044
A8: 2 | B8: =MASTER!B2 | E8: C/NO : | F8: =VLOOKUP(F6,MASTER!$B$2:$M$16,6,FALSE) -> 72 | H8: 11100011A
A9: 3 | B9: =MASTER!#REF! -> #REF! | E9: MADE IN KOREA | H9: 11100044A
B10: =MASTER!B49 -> 0 | D10: ----------------------
D11: =" TOTAL "&MASTER!G19&" PALLETS" -> TOTAL 2 PALLETS
D12: ="( TOTAL "&MASTER!G18&" CARTONS)" -> ( TOTAL 144 CARTONS) | H12: =MASTER!G18 -> 144

Sheet Skid
C2: pcs/skid
B3: E1490001119 | C3: 576
B4: E1490001135 | C4: 360
B5: E1490001136 | C5: 432
B6: E1490001141 | C6: 720
B7: E1490001134 | C7: 432
B8: 14900186K | C8: 900
B9: E1490001132 | C9: 540
B10: E1490001121 | C10: 360
B11: E1490001144 | C11: 864
B12: E1490001125 | C12: 144
B13: E1490001142 | C13: 240
B14: E1490001199 | C14: 320
... B37: E1490010273 | C37: 540

Sheet MASTER
A1: NO | B1: P/N | C1: QTY | D1: RAN | E1: CUM | F1: 박스적입 | G1: BOX_QTY | H1: DUE | K1: UNIT PRICE | L1: PO# | M1: NET WEIGHT | N1: Gross Weight | O1: pcs/skid | P1: Skid Qty | Q1: CBM
A2: 1 | B2: E3870015336A0 | C2: 14400 | D2: 60 | F2: 200 | G2: =C2/F2 -> 72 | H2: 6080 | K2: 0.4653 | L2: 2550001216 | M2: 0.027 | N2: =M2*C2 -> 388.8 | O2: 14400 | P2: =C2/O2 -> 1 | Q2: =P2*1.21 -> 1.21
A3: 2 | B3: E3870015347A0 | C3: 14400 | D3: 60 | F3: 200 | G3: =C3/F3 -> 72 | H3: 0 | K3: 0.3482 | L3: 2550001217 | M3: 0.025 | N3: =M3*C3 -> 360 | O3: 14400 | P3: =C3/O3 -> 1 | Q3: =P3*1.21 -> 1.21
A4: 3
A5: 4
A6: 5
A8: 6
A9: 7
A10: 8
A11: 9
A12: 10
A13: 11
A14: 12
A15: 13
A16: 14
C17: =SUM(C2:C16) -> 28800 | G17: =SUM(G2:G16) -> 144 | M17: 총 Net--> | N17: =SUM(N2:N16) -> 748.8 | P17: =SUM(P2:P16) -> 2 | Q17: =P17*1.21 -> 2.42
B18: =COUNTA(B2:B16) -> 2 | F18: Qty_box | G18: =ROUNDUP(G17,0) -> 144 | L18: 박스중량 | M18: 0.5 | N18: =N17+M19 -> 820.8
F19: Pallet | G19: 2 | L19: 박수총중량 | M19: =M18*G18 -> 72
G20: 1
C21: 2 | D21: 3 | E21: 4 | F21: 5 | G21: 6 | H21: 7 | I21: 8 | J21: 9 | K21: 10 | L21: 11 | M21: 12 | N21: 13
AE29: Invoice # | AF29: 인계자 | AG29: 인수자 | AH29: 차량번호
AE30: KCDN12-24

Sheet 출고증 (2)
A1: 수출 출고 확인증
A8: 인 계 자 | E8: Invoice N0. | I8: 출고 일자 | K8: 출고 시간
E9: =PA!H2 -> KCR26-06 | I9: =TODAY() -> 46168
A10: 경 창 정 공
E11: 차량번호
A15: No | B15: Part # | C15: 총 수량 | D15: PLT # | E15: 출고일
E16: 출고일#1 | F16: 확인 | G16: 출고일#2 | H16: 확인 | I16: 출고일#3 | J16: 확인 | K16: 최종확인
A18: 1 | B18: E1490001119 | C18: =MASTER!C2 -> 14400 | D18: =MASTER!P2 -> 1
A19: 2 | B19: E1490001135 | C19: =MASTER!C3 -> 14400 | D19: =MASTER!P3 -> 1
A20: 1 | B20: E1490001136 | C20: =MASTER!C4 -> 0 | D20: =MASTER!P4 -> 0
A21: 4 | B21: E1490001141 | C21: =MASTER!C5 -> 0 | D21: =MASTER!P5 -> 0
A22: 2 | B22: E1490001134 | C22: =MASTER!C6 -> 0 | D22: =MASTER!P6 -> 0
B23: E1490001132 | C23: =MASTER!C7 -> 0 | D23: =MASTER!P7 -> 0
A24: 3 | B24: E1490001121 | C24: =MASTER!C8 -> 0 | D24: =MASTER!P8 -> 0
A25: 4 | B25: E1490001146 | C25: =MASTER!C9 -> 0 | D25: =MASTER!P9 -> 0
A26: 8 | B26: E1490001125 | C26: =MASTER!C10 -> 0 | D26: =MASTER!P10 -> 0
A27: 9 | B27: E1490001111 | C27: =MASTER!C11 -> 0 | D27: =MASTER!P11 -> 0
A28: 10 | B28: E1490001142 | C28: =MASTER!C12 -> 0 | D28: =MASTER!P12 -> 0
A29: 11 | B29: E1490001144 | C29: =MASTER!C13 -> 0 | D29: =MASTER!P13 -> 0
A30: 12 | B30: E1490001149 | C30: =MASTER!C14 -> 0 | D30: =MASTER!P14 -> 0
A31: 5 | B31: E1590001025 | C31: =MASTER!C15 -> 0 | D31: =MASTER!P15 -> 0
A32: 6 | B32: C1490001238 | C32: =MASTER!C16 -> 0 | D32: =MASTER!P16 -> 0
A33: 7 | B33: E1490001232 | C33: =MASTER!#REF! -> #REF! | D33: =MASTER!#REF! -> #REF!
A34: 16 | B34: E1490001287 | C34: =MASTER!#REF! -> #REF! | D34: =MASTER!#REF! -> #REF!
A35: 17 | B35: E1490001293 | C35: =MASTER!#REF! -> #REF! | D35: =MASTER!#REF! -> #REF!
A36: 18 | B36: E1490001261 | C36: =MASTER!#REF! -> #REF! | D36: =MASTER!#REF! -> #REF!
A37: 16 | B37: E1490001262 | C37: =MASTER!#REF! -> #REF! | D37: =MASTER!#REF! -> #REF!
A38: 8 | B38: C1490001268 | C38: =MASTER!#REF! -> #REF! | D38: =MASTER!#REF! -> #REF!
A39: 9 | B39: E1490001266 | C39: =MASTER!#REF! -> #REF! | D39: =MASTER!#REF! -> #REF!
A40: 10 | B40: E1490001229 | C40: =MASTER!#REF! -> #REF! | D40: =MASTER!#REF! -> #REF!
A41: 19 | B41: E1490001153 | C41: =MASTER!#REF! -> #REF! | D41: =MASTER!#REF! -> #REF!
A42: 11 | B42: E1490001275 | C42: =MASTER!#REF! -> #REF! | D42: =MASTER!#REF! -> #REF!
A43: 12 | B43: C1490001283 | C43: =MASTER!#REF! -> #REF! | D43: =MASTER!#REF! -> #REF!
A44: 13 | B44: E1490001294 | C44: =MASTER!#REF! -> #REF! | D44: =MASTER!#REF! -> #REF!
... A48: 13 | B48: C1490018833A0 | C48: =MASTER!#REF! -> #REF! | D48: =MASTER!#REF! -> #REF!
D49: =SUM(D18:D48) -> #REF!
I56: 확 인

Sheet 원산지증명
A1: [별지 제6호의9서식]
A2: 미국과의 협정에 따른 원산지증명서 권고서식
A3: Certificate of Origin
A4: Korea-US Free Trade Agreement
A5: 1.Exporter (수출자) | C5: Name (성명) | D5: Kyung Chang Precision | G5: 2. Blanket Period
G6: (원산지포괄증명기간)
C7: Address(주소) | D7: 306-56, Jang-Dong, Dalseo-Gu, Daegu, Korea(704-190)
G8: 2015 01 01 2015 12 31
C9: Telephone (전화) | D9: 82 53 721 1844 | G9: (년) (월) (일) (년) (월) (일)
C10: Fax (팩스) | D10: 82 53 718 2494 | G10: From: __ __ __ __/__ __ /__ __ To: __ __ __ __/__ __ /__ __
C11: E-mail (전자주소) | D11: sylee@kc.co.kr | G11: (부터) (까지)
A13: 3.Producer (생산자) | C13: Name (성명) | D13: Kyung Chang Precision | G13: 4.Importer (수입자) | H13: Name (성명) | J13: Various
C15: Address(주소) | D15: 306-56, Jang-Dong, Dalseo-Gu, Daegu, Korea(704-190) | H15: Address(주소)
C17: Telephone (전화) | D17: 82 53 721 1844 | H17: Telephone (전화)
C19: Fax (팩스) | D19: 82 53 718 2494 | H19: Fax (팩스)
C21: E-mail (전자주소) | D21: sylee@kc.co.kr | H21: E-mail (전자주소) | J21: jadcock@borgwarner.com
A22: 5.원산지증명대상물품내역
A23: Serial No. | B23: Description of Good(s) | E23: Quantity & Unit | F23: HS No. | I23: Preference Criterion | K23: Country of Origin
A24: (연번) | B24: (품명ㆍ규격) | E24: (수량 및 단위) | F24: (품목번호 HS 6단위) | I24: (원산지결정기준) | K24: (원산지 국가)
A25: 1 | B25: E1490001119 | D25: Bracket Air Pump | F25: 830230 | I25: CTSH | K25: KR
B26: E1490001135 | D26: Bracket Air Pump | F26: 830230 | I26: CTSH | K26: KR
B27: E1490001136 | D27: Bracket Air Pump | F27: 830230 | I27: CTSH | K27: KR
B28: E1490001141 | D28: Bracket Air Pump | F28: 830230 | I28: CTSH | K28: KR
B29: E1490001134 | D29: Bracket Air Pump | F29: 830230 | I29: CTSH | K29: KR
B30: E1490001132 | D30: Bracket Air Pump | F30: 830230 | I30: CTSH | K30: KR
B31: E1490001121 | D31: Bracket Air Pump | F31: 830230 | I31: CTSH | K31: KR
B32: E1490001144 | D32: Bracket Air Pump | F32: 830230 | I32: CTSH | K32: KR
B33: E1490001125 | D33: Bracket Air Pump | F33: 830230 | I33: CTSH | K33: KR
B34: E1490001111 | D34: Bracket Air Pump | F34: 830230 | I34: CTSH | K34: KR
B35: E1490001142 | D35: Bracket Air Pump | F35: 830230 | I35: CTSH | K35: KR
B36: E1490001199 | D36: Bracket Air Pump | F36: 830230 | I36: CTSH | K36: KR
B37: E1490001149 | D37: Bracket Air Pump | F37: 830230 | I37: CTSH | K37: KR
... B59: C1490018833A0 | D59: Bracket Air Pump | F59: 830230 | I59: CTSH | K59: KR
A60: 6. Observations:
A61: (특이사항)
A62: I certify that:
A63: 본인은 다음 사항을 확인합니다.
A64: - The information in this document is true and accurate and I assume the responsibility for proving such representations.
A65: I understand that I am liable for any false statements or material omissions made on or in connection with this document.
A66: 상기 서식에 기재된 내용은 사실이고 정확하며, 기재된 사항에 대한 책임은 본인에게 있습니다. 이 증명서 또는 이와 관련한 허위 진술 또는 중대한 사실 누락에 대해서는 본인에게 책임이 있음을 확인합니다.
...
